Workbook

Sheet Sheet1
A1: Annexure | B1: Budgeted cost | C1: Actual Cost | D1: Remaining Cost
A2: Annexure I | B2: =Summary!C9 -> 179850 | C2: =Summary!E9 -> 0 | D2: =B2-C2 -> 179850
A3: Annexure II | B3: =Summary!C12 -> 36193 | C3: =Summary!E12 -> 20621.784 | D3: =B3-C3 -> 15571.216
A4: Annexure III | B4: =Summary!C15 -> 936075 | C4: =Summary!E15 -> 886356.69 | D4: =B4-C4 -> 49718.31
A5: Annexure IV | B5: =Summary!C18 -> 275000 | C5: =Summary!E18 -> 127321 | D5: =B5-C5 -> 147679
A6: Annexure V | B6: =Summary!C21 -> 917500 | C6: =Summary!E21 -> 692348 | D6: =B6-C6 -> 225152
A7: Annexure VI | B7: =Summary!C24 -> 6475383.6 | C7: =Summary!E24 -> 6527134 | D7: =B7-C7 -> -51750.472
A8: Annexure VII | B8: =Summary!C27 -> 1760997 | C8: =Summary!E27 -> 1534282.4 | D8: =B8-C8 -> 226714.6
A9: Annexure VIII | B9: =Summary!C30 -> 1320000 | C9: =Summary!E30 -> 712385.22 | D9: =B9-C9 -> 607614.78
A10: Annexure IX | B10: =Summary!C33 -> 1856500 | C10: =Summary!E33 -> 1107431.5 | D10: =B10-C10 -> 749068.54
A11: Annexure X | B11: =Summary!C35 -> 4946840 | C11: =Summary!E35 -> 3498986.6 | D11: =B11-C11 -> 1447853.4
A12: Annexure XI | B12: =Summary!C37 -> 257150 | C12: =Summary!E37 -> 64492.822 | D12: =B12-C12 -> 192657.18
A13: T
C20: Total budgeted Cost | D20: Total Actual Cost | E20: Remaining Cost
C21: =SUM(B2:B12) -> 18961489 | D21: =SUM(C2:C12) -> 15171360 | E21: =C21-D21 -> 3790128.5
C40: Major Drilling Eq | D40: Cost
C41: Top Drive | D41: ='Ann VI-Drill'!N7 -> 687875.43
C42: Iron Rouchneck | D42: ='Ann VI-Drill'!N16 -> 738836.46
C43: Draw-works | D43: =SUM('Ann VI-Drill'!N11:N12) -> 999624
C44: Mud pumps | D44: ='Ann VI-Drill'!N15 -> 607787
C45: Crown block | D45: ='Ann VI-Drill'!N5 -> 97058.98
C46: Travelling Block | D46: ='Ann VI-Drill'!N9 -> 143156
C47: Rotary Table | D47: ='Ann VI-Drill'!N14 -> 127166.3
C48: Deadline Anchor | D48: ='Ann VI-Drill'!N10 -> 11282
C49: BOP | D49: =SUM('Ann VI-Drill'!N18:N19) -> 1363788
C50: Diverter | D50: ='Ann VI-Drill'!N17 -> 415300.7
C51: Manifold | D51: ='Ann VI-Drill'!N30 -> 387579.24
D52: =SUM(D41:D51) -> 5579454.1

Sheet Dashboard

Sheet Summary
A1: BUDGETED VS ACTUAL EXPENSES FOR JINDAL PIONEER RECERTIFICATION & MISCELLANEOUS SERVICES SUMMARY SHEET 17-03-2026
B2: SHIPYARD | G2: 1 | H2: 87
A3: Sr. No. | B3: Description | C3: Budgetory Cost | D3: Budgetory cost | E3: Actual Cost | F3: Remaining Cost
C4: (in USD) | D4: (in INR) | E4: (USD) | F4: (USD) | H4: Annexure Ref
A6: A | B6: ='Ann I'!C2 -> TOWAGE EXPENSES
A7: I | B7: Marine Warranty Surveyor ( Lamprell to Khalid Port) | C7: ='Ann I'!C12 -> 15650 | D7: =C7*H2 -> 1361550 | E7: ='Ann I'!E12 -> 0 | F7: ='Ann I'!F12 -> 15650 | H7: ='[1]Annexure I'!G2 -> Annexure I
A8: II | B8: TOW BOAT AND OTHER EXPENSES | C8: ='Ann I'!C22 -> 164200 | D8: =C8*H2 -> 14285400 | E8: ='Ann I'!E23 -> 0 | F8: ='Ann I'!F22 -> 164200
B9: Total | C9: =SUM(C7:C8) -> 179850 | D9: =SUM(D7:D8) -> 15646950 | E9: =SUM(E7:E8) -> 0 | F9: =SUM(F7:F8) -> 179850
A10: B | B10: ='Ann II'!B2:E2 -> CLASS RELATED EXPENSES
A11: I | B11: CLASS SURVEY AND RELATED EXPENSES | C11: ='Ann II'!C10 -> 36193 | D11: =C11*87 -> 3148791 | E11: ='Ann II'!I10 -> 20621.784 | F11: ='Ann II'!J10 -> 15571.216 | H11: ='[1]Annexure II '!G2 -> Annexure II
B12: Total | C12: =SUM(C11:C11) -> 36193 | D12: =SUM(D11:D11) -> 3148791 | E12: ='Ann II'!I10 -> 20621.784 | F12: ='Ann II'!J10 -> 15571.216
A13: C | B13: ='Ann III'!B2:R2 -> KHALID AND LAMPRELL PORT EXPENSES
A14: i | B14: Berthing Charges, fuel, water & Other Related Works | C14: ='Ann III'!H18 -> 936075 | D14: =C14*87 -> 81438525 | E14: ='Ann III'!N18 -> 886356.69 | F14: ='Ann III'!O18 -> 151718.31 | H14: Annexure III
B15: Total | C15: =C14 -> 936075 | D15: =SUM(D14:D14) -> 81438525 | E15: ='Ann III'!N18 -> 886356.69 | F15: ='Ann III'!O18 -> 151718.31
A16: ='[1]Annexure IV '!A6 -> D | B16: Clearing Forwarding and Custom Duty Charges
A17: i | B17: Clearing, Forwarding charges Customs Duty charges etc. | C17: ='Ann IV'!C10 -> 275000 | D17: =C17*87 -> 23925000 | E17: ='Ann IV'!E10 -> 127321 | F17: ='Ann IV'!F10 -> 147679 | H17: ='[1]Annexure IV '!G2 -> Annexure IV
B18: Total | C18: =SUM(C17:C17) -> 275000 | D18: =SUM(D17:D17) -> 23925000 | E18: ='Ann IV'!E10 -> 127321 | F18: ='Ann IV'!F10 -> 147679
A19: E | B19: ='[1]Annexure V'!B6:E6 -> Crew Expenses
A20: i | B20: Crew flights, visa, CDC, Catering, Communication, Salary | C20: ='Ann V'!C12 -> 917500 | D20: =C20*87 -> 79822500 | E20: ='Ann V'!E12 -> 692348 | F20: ='Ann V'!F12 -> 225152 | H20: ='[1]Annexure V'!G2 -> Annexure V
B21: Total | C21: =SUM(C20:C20) -> 917500 | D21: =SUM(D20:D20) -> 79822500 | E21: ='Ann V'!E12 -> 692348 | F21: ='Ann V'!F12 -> 225152
A22: F | B22: Drilling, Well Control and Solid Control
A23: i | B23: Work to be done - Drilling | C23: ='Ann VI-Drill'!F62 -> 6475383.6 | D23: =C23*87 -> 5.6335837e+08 | E23: ='Ann VI-Drill'!N62 -> 6527134 | F23: ='Ann VI-Drill'!O62 -> -51750.472 | H23: ='[1]An VI - Drill'!K2 -> Annexure VI
B24: Total | C24: =SUM(C23:C23) -> 6475383.6 | D24: =SUM(D23:D23) -> 5.6335837e+08 | E24: ='Ann VI-Drill'!N62 -> 6527134 | F24: ='Ann VI-Drill'!O62 -> -51750.472
A25: G | B25: Mechanical
B26: Work to be done - Mechanical | C26: ='Ann VII-Mech'!F33 -> 1760997 | D26: =C26*H2 -> 153206739 | E26: ='Ann VII-Mech'!M33 -> 1534282.4 | F26: ='Ann VII-Mech'!N33 -> 226714.6 | H26: ='[1]An VII - Mech'!K2 -> Annexure VII
B27: Total | C27: {=C26:D26} -> 1760997 | D27: 153206739 | E27: ='Ann VII-Mech'!M33 -> 1534282.4 | F27: ='Ann VII-Mech'!N33 -> 226714.6
A28: H | B28: Electrical and Power Plant
A29: i | B29: Work to be done - Electircal,power | C29: ='Ann VIII-Elec'!F41 -> 1320000 | D29: =C29*H2 -> 114840000 | E29: ='Ann VIII-Elec'!N41 -> 712385.22 | F29: ='Ann VIII-Elec'!O41 -> 607614.78 | H29: ='[1]An VIII -Elec'!K2 -> Annexure VIII
B30: Total | C30: =SUM(C29:C29) -> 1320000 | D30: =D29 -> 114840000 | E30: ='Ann VIII-Elec'!N41 -> 712385.22 | F30: ='Ann VIII-Elec'!O41 -> 607614.78
A31: I | B31: Lifting gear, Marine and Safety
A32: i | B32: Work to be done - Marine and Safety | C32: ='Ann IX-Marine'!F66 -> 1856500 | D32: =C32*87 -> 161515500 | E32: ='Ann IX-Marine'!N66 -> 1107431.5 | F32: ='Ann IX-Marine'!O66 -> 749068.54 | H32: ='[1]An IX - Marine'!K2 -> Annexure IX
B33: Total | C33: =SUM(C32:C32) -> 1856500 | D33: =D32 -> 161515500 | E33: ='Ann IX-Marine'!N66 -> 1107431.5 | F33: ='Ann IX-Marine'!O66 -> 749068.54
A34: J | B34: Additional Items/ Shortfall as per ONGC tender | H34: Annexure X
B35: Total | C35: ='Ann X-Contractual Req'!C49 -> 4946840 | D35: =C35*87 -> 430375080 | E35: ='Ann X-Contractual Req'!J49 -> 3498986.6 | F35: ='Ann X-Contractual Req'!K49 -> 1447853.4
A36: K | B36: Missing items from rig Jindal Pioneer -post handover from Saipem | H36: Annexure XI
B37: Total | C37: ='Ann XI-Missing items Saipem'!C20 -> 257150 | D37: =C37*87 -> 22372050 | E37: ='Ann XI-Missing items Saipem'!H20 -> 64492.822 | F37: ='Ann XI-Missing items Saipem'!I20 -> 192657.18 | H37: Not included in Total
A38: TOTAL | C38: =SUM(C9+C12+C15+C18+C21+C24+C27+C30+C33+C35+C37) -> 18961489 | D38: =SUM(D9+D12+D15+D18+D21+D24+D27+D30+D33+D35+D37) -> 1.6496495e+09 | E38: =E9+E12+E15+E18+E21+E24+E27+E30+E33+E35+E37 -> 15171360 | F38: =F9+F12+F15+F18+F21+F24+F27+F30+F33+F35 -> 3699471.3
A40: TOTAL (IN USD MILLION) (Annex I to X) | C40: =C38/1000000 -> 18.961489 | E40: =E38/1000000 -> 15.17136 | F40: =F38/1000000 -> 3.6994713

Sheet Ann I
A1: BUDGETED EXPENSES FOR JINDAL PIONEER RECERTIFICATION & MISCELLANEOUS SERVICES -ANNEXURE I
A2: A | C2: TOWAGE EXPENSES
A3: Sr. No. | B3: Description | C3: Budgetory Cost | D3: Budgetory Cost | E3: Actual Cost | F3: Surplus/Exceeded | G3: Remarks
C4: (in USD) | D4: (in INR) | E4: (in USD) | F4: (in USD)
A7: I | C7: Marine Warranty Surveyor ( Lamprell to Khalid Port to India)
A8: 1 | B8: Location Certifcate Approval | C8: =1925*2 -> 3850 | D8: =C8*87 -> 334950 | E8: 0 | F8: =C8-E8 -> 3850 | G8: Considering Location Approval at Port Khalid and India 1925$ per approval
A9: 2 | B9: Towage Certificate Approval | C9: =900*2 -> 1800 | D9: =C9*87 -> 156600 | E9: 0 | F9: =C9-E9 -> 1800 | G9: 900$ per approval (2 considered)
A10: 3 | B10: Other miscellaneous charges towards flight tickets, transportation etc. of MWS | C10: 2000 | D10: =C10*87 -> 174000 | E10: 0 | F10: =C10-E10 -> 2000
A11: 4 | B11: Day Rate of Onboard Surveyor(Rig Mover/MWS) | C11: =2000*4 -> 8000 | D11: =C11*87 -> 696000 | E11: 0 | F11: =C11-E11 -> 8000 | G11: Considered for 4 days Rig move from Hamriyah to port Khalid
A12: Total | C12: =SUM(C8:C11) -> 15650 | D12: =SUM(D8:D11) -> 1361550 | E12: =SUM(E8:E11) -> 0 | F12: =SUM(F8:F11) -> 15650
A13: II | C13: Tow Boat & other Port Expenses
A14: 6 | B14: Sea Bed Survey(Khalid Port) | C14: 4000 | D14: =C14*87 -> 348000 | E14: 0 | F14: =C14-E14 -> 4000 | G14: Considered 1 Sea bed surveys (one in port khalid)
A15: 7 | B15: Marine Weather Forecast | C15: =50*4 -> 200 | D15: =C15*87 -> 17400 | E15: 0 | F15: =C15-E15 -> 200 | G15: Considered for 4 days Rig move from Hamriyah to port Khalid
A16: 8 | B16: Tow Boat Charges -Lamprell to port khalid | C16: 150000 | D16: =C16*87 -> 13050000 | E16: 0 | F16: =C16-E16 -> 150000 | G16: Includes SR NO (9,10,11,12)
A17: 9 | B17: Inward & Outward Port Clearance for Rig | D17: =C17*87 -> 0 | E17: 0 | F17: =C17-E17 -> 0
A18: 10 | B18: Inward & Outward Port Clearance for Tug | D18: =C18*87 -> 0 | E18: 0 | F18: =C18-E18 -> 0
A19: 11 | B19: Pilot Charges | D19: =C19*87 -> 0 | E19: 0 | F19: =C19-E19 -> 0
A20: 12 | B20: Diesel Consumption while Rig Tow | D20: =C20*87 -> 0 | E20: 0 | F20: =C20-E20 -> 0
A21: 13 | B21: Contiengency & other misc charges | C21: 10000 | D21: =C21*87 -> 870000 | E21: 0 | F21: =C21-E21 -> 10000
C22: =SUM(C14:C21) -> 164200 | D22: =C22*87 -> 14285400 | E22: 0 | F22: =C22-E22 -> 164200
A23: Total | C23: =SUM(C12,C22) -> 179850 | D23: =SUM(D12,D22) -> 15646950 | E23: =SUM(E14:E22) -> 0 | F23: =C23-E23 -> 179850
A25: Note: Cost for towing from Khalid Port to Mumbai harbour is not considered.

Sheet Ann II
A1: BUDGETED EXPENSES FOR JINDAL PIONEER RECERTIFICATION & MISCELLANEOUS SERVICES -ANNEXURE II
A2: B | B2: CLASS RELATED EXPENSES
A3: Sr. No. | B3: Description | C3: Budgetory Cost | D3: Actual cost | E3: Budgetory Cost | F3: Local Actual Cost | G3: Local cost in USD | H3: Local cost in INR | I3: Total cost in USD | J3: Surplus/Exceeded | K3: MR NO | L3: PO NO | M3: Remarks | N3: CS VALUE TILL DATE
C4: (in USD) | D4: (in USD) | E4: (in INR)
A6: I | B6: CLASS SURVEY & RELATED EXPENSES
A7: 1 | B7: Spudcan Internal and External anode replacement | C7: =16193 -> 16193 | E7: =C7*87 -> 1408791 | F7: 56597 | H7: 42697.5 | I7: =F7*0.27+G7+H7*0.01149 -> 15771.784 | J7: =C7-I7 -> 421.21573 | K7: RJPSL/BO/2526/00002 RJPDD/BO/2526/00013 | L7: RJPSL/IPO/2526/00001 RJPDD/LPO/2526/00001 | M7: Anode cost- $16192.6 | N7: USD 16192.6 Anode cost
A8: 2 | B8: Donut NDT | C8: 5000 | I8: =F8*0.27+G8+H8*0.01149 -> 0 | J8: =C8-I8 -> 5000
A9: 3 | B9: DNV Survey and Flag charges | C9: 15000 | E9: =C9*87 -> 1305000 | G9: 4850 | I9: =F9*0.27+G9+H9*0.01149 -> 4850 | J9: =C9-I9 -> 10150 | K9: RJPSL/BO/2526/00189 | L9: RJPSL/IPO/2526/00148 | M9: Considered actual amount
A10: Total | C10: =SUM(C7:C9) -> 36193 | E10: =SUM(E7:E9) -> 2713791 | I10: =SUM(I7:I9) -> 20621.784 | J10: =C10-I10 -> 15571.216

Sheet Ann III
A1: BUDGETED EXPENSES FOR JINDAL PIONEER RECERTIFICATION & MISCELLANEOUS SERVICES - ANNEXURE III
A2: A | B2: KHALID AND LAMPRELL PORT EXPENSES
A3: S.No | B3: DESCRIPTION | C3: UOM | D3: Qty | E3: (USD)/Day Lamprell | F3: (USD)/Day Khalid | G3: BUDGETORY COST (USD) LAMPRELL HAMRIYAH (130 DAYS) | H3: BUDGETORY COST (USD) LAMPRELL HAMRIYAH(10 DAYS) AND PORT KHALID(120 DAYS) | I3: BUDGETORY COST (INR) | J3: Actual cost (AED) | K3: Actual cost (USD) | L3: VOR (USD) | M3: Projected cost | N3: Actucal Total Cost (USD) | O3: Surplus/Exceeded | P3: MR NO | Q3: PO NO | R3: Remarks
A4: 1 | B4: Agency Fee | C4: Mon | R4: Considered in CHA- Ann IV SR no 1
A5: 2 | B5: Port Due | C5: Ea | R5: Considered in CHA- Ann IV SR no 1
A6: 3 | B6: Port parking charges | C6: day | D6: 130 | E6: 600 | F6: 450 | G6: =E6*130 -> 78000 | H6: =E6*10+ F6*120 -> 60000 | I6: =H6*87 -> 5220000 | K6: =162*600 -> 97200 | N6: =J6*0.27+K6+L6+M6 -> 97200 | O6: =G6-N6 -> -19200 | R6: Lamprell Hamriyah Charges @ $600 /day for 10 days Khalid Port Charges @ $450/ day for 4 months
A7: 4 | B7: Berthing Charges, Other miscellaneous charges (Fire team),MISCELLANEOUS (STAGING/BARRICADING) | C7: day | D7: 130 | E7: 150 | F7: 200 | G7: =E7*130 -> 19500 | H7: =E7*10 + F7*120 -> 25500 | I7: =H7*87 -> 2218500 | L7: 15000 | N7: =J7*0.27+K7+L7+M7 -> 15000 | O7: =G7-N7 -> 4500 | R7: Lamprell Hamriyah miscellaneous -$150/day Khalid port miscellaneous - $200/day
A8: 5 | B8: Additional shiyard equipment and services | C8: day | D8: 130 | E8: 1750 | F8: 1000 | G8: =E8*130 -> 227500 | H8: =E8*10 + F8*120 -> 137500 | I8: =H8*87 -> 11962500 | L8: =36113+4750+130200 -> 171063 | N8: =J8*0.27+K8+L8+M8 -> 171063 | O8: =G8-N8 -> 56437 | Q8: Ut gauging, MPI Stell replacement Other miscellaneous | R8: Lamprell additional charges- $1750/day Khalid additional charges- $1000/day ($14/hour charges for electricain mechnanic, riggers and other equipment charges - forklift/cranes)
A9: 6 | B9: Pre - handover equipment endurance test | C9: lumpsum | G9: 18000 | H9: 18000 | I9: =H9*87 -> 1566000 | L9: 10000 | N9: =J9*0.27+K9+L9+M9 -> 10000 | O9: =G9-N9 -> 8000 | R9: Estimated
A10: 7 | B10: Catering charges in Lamprell yard pre hand over | C10: day | D10: 45 | E10: 25 | G10: =45*25*15 -> 16875 | H10: =45*25*15 -> 16875 | I10: =H10*87 -> 1468125 | L10: 16875 | N10: =J10*0.27+K10+L10+M10 -> 16875 | O10: =G10-N10 -> 0 | R10: Estimated $25/day considerd for 15 persons for 45 days
A11: Total | G11: =SUM(G6:G10) -> 359875 | H11: =SUM(H6:H10) -> 257875 | I11: =SUM(I4:I10) -> 22435125 | N11: =SUM(N6:N10) -> 310138 | O11: =G11-N11 -> 49737
A12: B
A13: S.No | B13: DESCRIPTION | C13: UOM | D13: (QTY) | E13: (USD) | R13: Remarks
A14: 9 | B14: Lube oil for engines, Mud pump. Hydraulic oil for HPU, KOOMI Unit, Jacking Gearbox etc | C14: BBL | D14: 42 | G14: 100000 | H14: 100000 | I14: =H14*87 -> 8700000 | J14: =113624+36573+29400 -> 179597 | N14: =J14*0.27+K14+L14+M14 -> 48491.19 | O14: =G14-N14 -> 51508.81 | P14: RJPSL/BO/2526/00017 RJPSL/BO/2526/00282 | Q14: RJPSL/IPO/2526/00021, RJPSL/IPO/2526/00098 RJPSL/IPO/2526/00187 RJPSL/IPO/2526/00188 | R14: 15 bbl for 3 nos main Engines & 5 bbl for Jacking system , 5 bbl for Koomey unit, 3 bbl for Drawworks,8 bbls for Mud pump, 1 bbl Compressor oil & 5 bbls contigency.
A15: 10 | B15: Supply of Pot Water in Harbour (Approx.) | C15: MT | D15: 10 | E15: =10*13 -> 130 | G15: =10*140*13 -> 18200 | H15: =10*140*13 -> 18200 | I15: =H15*87 -> 1583400 | J15: =12150+4050+4050 -> 20250 | N15: =J15*0.27+K15+L15+M15 -> 5467.5 | O15: =G15-N15 -> 12732.5 | P15: RJPSL/BO/2627/00001 RJPSL/BO/2526/00470 RJPSL/BO/2526/00345 RJPSL/BO/2526/00029, RJPSL/BO/2526/00118, RJPSL/IPO/2526/00144 | Q15: RJPSL/IPO/2627/00013 RJPSL/IPO/2526/00330 RJPSL/IPO/2526/00226 RJPSL/IPO/2526/00032 RJPSL/IPO/2526/00093 RJPSL/IPO/2526/00144 | R15: Consumption-10MT/day Considered for 140 days at yard at $13/day
A16: 11 | B16: Diesel for Rig | C16: KL | D16: 5 | E16: 800 | G16: =5*800*140 -> 560000 | H16: =5*800*140 -> 560000 | I16: =H16*87 -> 48720000 | K16: =104100+47610+43250+43250+34050 -> 272260 | M16: 250000 | N16: =J16*0.27+K16+L16+M16 -> 522260 | O16: =G16-N16 -> 37740 | P16: RJPSL/BO/2526/00459 RJPSL/BO/2526/00344 RJPSL/BO/2526/00028, RJPSL/BO/2526/00117 | Q16: RJPSL/IPO/2526/00352 RJPSL/IPO/2526/00225 RJPSL/IPO/2526/00031, RJPSL/IPO/2526/00101 | R16: $800 /KL for 5KL for 140 days 110 days at yard & 30 days for tow to mumbai harbour and then to client designated location.
A17: Total | G17: =SUM(G14:G16) -> 678200 | H17: =SUM(H14:H16) -> 678200 | I17: =SUM(I14:I16) -> 59003400 | N17: =SUM(N14:N16) -> 576218.69 | O17: =G17-N17 -> 101981.31
A18: Grand Total | G18: =SUM(G11,G17) -> 1038075 | H18: =SUM(H11,H17) -> 936075 | I18: =SUM(I11,I17) -> 81438525 | N18: =SUM(N11,N17) -> 886356.69 | O18: =SUM(O11,O17) -> 151718.31
B20: All port charges are considered after the handover of the rig from Saipem to Jindal, Post November 24.

Sheet Ann IV
A1: BUDGETED EXPENSES FOR JINDAL PIONEER RECERTIFICATION & MISCELLANEOUS SERVICES- ANNEXURE IV
A2: Clearing Forwarding and Custom Duty Charges
A3: Sr. No. | B3: Description | C3: Budgetory Cost | D3: Budgetory cost | E3: Actual total cost | F3: Surplus/Exceeded | G3: Remarks
C4: (in USD) | D4: (in INR) | E4: (USD)
A6: D | B6: Agency Charges / Transportation
A7: 1 | B7: Overseas Freight & Forwarding Expenses | C7: 200000 | D7: =C7*87 -> 17400000 | E7: =101047+26274 -> 127321 | F7: =C7-E7 -> 72679 | G7: Ref -Jindal Exp 23
A8: 2 | B8: Customs Formalities and customs charges etc | C8: 75000 | D8: =C8*87 -> 6525000 | F8: =C8-E8 -> 75000 | G8: Ref -Jindal Exp 23
A10: Total | C10: =SUM(C7:C8) -> 275000 | D10: =SUM(D7:D8) -> 23925000 | E10: =SUM(E7:E9) -> 127321 | F10: =C10-E10 -> 147679

Sheet Ann V
A1: BUDGETED EXPENSES FOR JINDAL PIONEER RECERTIFICATION & MISCELLANEOUS SERVICES -ANNEXURE V
A2: Crew flights, visa, CDC , Catering , Communication and salary
A3: Sr. No. | B3: Description | C3: Budgetory Cost | D3: Budgetory cost | E3: Actual Total cost | F3: Surplus/Exceeded | G3: Remarks
C4: (in USD) | D4: (in INR) | E4: (in USD)
A6: E | B6: Crew Expenses
A7: 1 | B7: Catering & services onboard | C7: =17*50*150 -> 127500 | D7: =C7*87 -> 11092500 | E7: =3300+16357+20058.5+23710.5+23331 -> 86757 | F7: =C7-E7 -> 40743 | G7: 50 person onboard @ USD 17/ person/ day for 150 days 3Cook @ USD 1050/ month, 4- Steward @ USD 735/ea month - for 6 months
A8: 2 | B8: Crew/Contractor Transport & Accomodation,local and Flight Tickets | C8: 60000 | D8: =C8*87 -> 5220000 | E8: =60500+11150+14910 -> 86560 | F8: =C8-E8 -> -26560 | G8: CDC / VISA Fee, Sign Off / Flight Tickets / Transportation Sign on-off considered for 30crew
A9: 3 | B9: Crew Salary | C9: =3000*60 + 4500*120 -> 720000 | D9: =C9*87 -> 62640000 | E9: =508245+9136 -> 517381 | F9: =C9-E9 -> 202619 | G9: $3000/day considerd for 60 days and $4500/day considered for 120 days.
A10: 4 | B10: Internet for Communication | C10: 10000 | D10: =C10*87 -> 870000 | E10: =1650 -> 1650 | F10: =C10-E10 -> 8350 | G10: Etisalat for 180 days
A12: Total | C12: =SUM(C7:C10) -> 917500 | D12: =SUM(D7:D10) -> 79822500 | E12: =SUM(E7:E10) -> 692348 | F12: =C12-E12 -> 225152

Sheet Ann VI-Drill
A1: BUDGETED EXPENSES FOR JINDAL PIONEER RECERTIFICATION & MISCELLANEOUS SERVICES - ANNEXURE VI
A2: F | C2: Drilling, Well Control and Solid Control
A3: Sr. No. | B3: Material Code | C3: Area | D3: DEPARTMENT / JOB DESCRIPTION | E3: WORK TO BE CARRIED OUT BY | F3: Budgetory Cost (USD) | G3: BUDGETORY COST (INR) | H3: Actual Cost Local (AED) | I3: Actual Cost Local (USD) | J3: Actual Cost Local (INR) | K3: Actual Cost Import (USD) | L3: VOR (USD) | M3: Projected Cost | N3: Actucal Total Cost (USD) | O3: Surplus/Exceeded | P3: MR NO | Q3: PO NO | R3: Remarks | S3: PO VALUE TILL DATE
A4: 1 | B4: 301073001 | C4: Derrick | D4: Derrick/Mast - CAT III inspection ,including TDS Dolly tracks bolt inspection& Drop Survey along with Remedial derrick handrails structural alignment and crown ladder allignment | E4: Third Party | F4: 25000 | G4: =F4*87 -> 2175000 | H4: =6200+4583+3209+4333 -> 18325 | K4: =7898+10530 -> 18428 | L4: 20670 | N4: =H4*0.27+I4+J4*0.01149+K4+L4+M4 -> 44045.75 | O4: =F4-N4 -> -19045.75 | P4: RJPSL/BO/2526/00391 RJPSL/BO/2526/00391 RDDPL/BO/2526/00148 | Q4: RJPSL/IPO/2526/00327, RJPSL/IPO/2526/00328 RJPSL/IPO/2526/00316, RJPSL/IPO/2526/00317 RDDPL/IPO/2526/00124 | R4: Estimated
A5: 2 | B5: 302302001 | C5: Drilling | D5: Crown Block/Cluster sheaves/Fastline/Deadline/Deflector Sheaves - CAT IV | E5: OEM/API | F5: 99918 | G5: =F5*87 -> 8692866 | K5: 97058.98 | N5: =H5*0.27+I5+J5*0.01149+K5+L5+M5 -> 97058.98 | O5: =F5-N5 -> 2859.02 | P5: RDDPL/BO/2526/00008 | Q5: RDDPL/IPO/2526/00049 | R5: CS -ABCO Cost considered as per CS value, cost may increase post D&I
A6: 3 | C6: Texas Deck | D6: Texas Deck - CTU platform | F6: 5000 | G6: =F6*87 -> 435000 | N6: =H6*0.27+I6+J6*0.01149+K6+L6+M6 -> 0 | O6: =F6-N6 -> 5000
A7: 4 | B7: 313314000 | C7: Drilling | D7: Top Drive - Overhual- CAT IV and Commisisioning. | E7: OEM/API | F7: 578164 | G7: =F7*87 -> 50300268 | K7: =566250.43+121625 -> 687875.43 | N7: =H7*0.27+I7+J7*0.01149+K7+L7+M7 -> 687875.43 | O7: =F7-N7 -> -109711.43 | P7: RDDPL/BO/2526/00192 RDDPL/BO/2526/00002 | Q7: RDDPL/IPO/2526/00153 RDDPL/IPO/2526/00045 | R7: PO- NOV Cost considered as per PO value, cost may increase post D&I | S7: 578163.52
C8: Drilling | D8: Well center - Allignement | E8: OEM/API | F8: 10000 | G8: =F8*87 -> 870000 | N8: =H8*0.27+I8+J8*0.01149+K8+L8+M8 -> 0 | O8: =F8-N8 -> 10000 | R8: Estimated
A9: 5 | B9: 303303001 | C9: Drilling | D9: Travelling Block - CAT IV | E9: OEM/API | F9: 81906 | G9: =F9*87 -> 7125822 | K9: =160306-17150 -> 143156 | N9: =H9*0.27+I9+J9*0.01149+K9+L9+M9 -> 143156 | O9: =F9-N9 -> -61250 | P9: RDDPL/BO/2526/00007, RDDPL/BO/2526/00073 | Q9: RDDPL/IPO/2526/00048, RDDPL/IPO/2526/00079 | R9: CS -ABCO Cost considered as per PO value, cost may increase post D&I
A10: 6 | B10: 317317001 | C10: Drilling | D10: Deadline Anchor - CAT IV | E10: OEM/API | F10: 26707 | G10: =F10*87 -> 2323509 | K10: =9832+1450 -> 11282 | N10: =H10*0.27+I10+J10*0.01149+K10+L10+M10 -> 11282 | O10: =F10-N10 -> 15425 | P10: RDDPL/BO/2526/00157 RDDPL/BO/2526/00009, RDDPL/BO/2526/00065 | Q10: RDDPL/IPO/2526/00128 RDDPL/IPO/2526/00003, RDDPL/IPO/2526/00031 | R10: CS -ABCO only for Inspection Cost considered as per CS value, cost may increase post D&I
A11: 7 | B11: 312312001 | C11: Drilling | D11: Draw Works - CAT IV | E11: OEM/API | F11: 567761 | G11: =F11*87 -> 49395207 | K11: 660223 | N11: =H11*0.27+I11+J11*0.01149+K11+L11+M11 -> 660223 | O11: =F11-N11 -> -92462 | P11: RDDPL/BO/2526/00003, RDDPL/BO/2526/00092 | Q11: RDDPL/IPO/2526/00046, RDDPL/IPO/2526/00101 | R11: PO- NOV Cost considered as per PO value, cost may increase post D&I | S11: 567760.57
E12: Brake stop plate to be changed | F12: 57338 | G12: =F12*87 -> 4988406 | K12: 339401 | N12: =H12*0.27+I12+J12*0.01149+K12+L12+M12 -> 339401 | O12: =F12-N12 -> -282063 | P12: RDDPL/BO/2526/00191 | Q12: RDDPL/IPO/2526/00152 | R12: Estimated
A13: 8 | C13: Drilling | D13: Drill line spool | F13: 50000 | G13: =F13*87 -> 4350000 | N13: =H13*0.27+I13+J13*0.01149+K13+L13+M13 -> 0 | O13: =F13-N13 -> 50000 | R13: Estimated
A14: 9 | B14: 313315001 | C14: Drilling | D14: Rotary Table - CAT IV | E14: OEM/API | F14: 73582 | G14: =F14*87 -> 6401634 | H14: 90 | K14: =113222+13920 -> 127142 | N14: =H14*0.27+I14+J14*0.01149+K14+L14+M14 -> 127166.3 | O14: =F14-N14 -> -53584.3 | P14: RDDPL/BO/2526/00006, RDDPL/BO/2526/00114, RDDPL/BO/2526/00091, RDDPL/BO/2526/00113 | Q14: RDDPL/IPO/2526/00002, RDDPL/IPO/2526/00092, RDDPL/IPO/2526/00096, RDDPL/IPO/2526/00097 | R14: CS-ABCO Cost considered as per CS value, cost may increase post D&I
A15: 10 | B15: 325325001 | C15: Drilling | D15: Mud Pumps - CAT IV | E15: OEM/API | F15: 590676 | G15: =F15*87 -> 51388812 | K15: =598770+562+3123+5332 -> 607787 | N15: =H15*0.27+I15+J15*0.01149+K15+L15+M15 -> 607787 | O15: =F15-N15 -> -17111 | P15: RDDPL/BO/2526/00166 RDDPL/BO/2526/00139 RDDPL/BO/2526/00004, RDDPL/BO/2526/00072 | Q15: RDDPL/IPO/2526/00131 RDDPL/IPO/2526/00112 RDDPL/IPO/2526/00047, RDDPL/IPO/2526/00065 | R15: CS-ABCO Cost considered as per CS value, cost may increase post D&I
A16: 11 | B16: 325053001 | C16: Drilling | D16: Iron Roughneck - CAT IV | E16: Third Party | F16: =422047+16575 -> 438622 | G16: =F16*87 -> 38160114 | K16: =432160.46+306676 -> 738836.46 | N16: =H16*0.27+I16+J16*0.01149+K16+L16+M16 -> 738836.46 | O16: =F16-N16 -> -300214.46 | P16: RDDPL/BO/2526/00190 RDDPL/BO/2526/00005 | Q16: RDDPL/IPO/2526/00151 RDDPL/IPO/2526/00004 | R16: CS- NOV Cost considered as per CS value, cost may increase post D&I | S16: 432160.49
A17: 12 | B17: 334334001 | C17: Diverter System | D17: Diverter is due for 5 year recertification with COC | E17: Third Party | F17: 276185.56 | G17: =F17*87 -> 24028144 | K17: =268926.7+35306+111068 -> 415300.7 | N17: =H17*0.27+I17+J17*0.01149+K17+L17+M17 -> 415300.7 | O17: =F17-N17 -> -139115.14 | P17: RDDPL/BO/2526/00137 RDDPL/BO/2526/00022, RDDPL/BO/2526/00130 RDDPL/BO/2526/00001 | Q17: RDDPL/IPO/2526/00113 RDDPL/IPO/2526/00005, RDDPL/IPO/2526/00106 RDDPL/IPO/2526/00040 | R17: CS- OIL STATES Cost considered as per CS value, cost may increase post D&I
A18: 13 | B18: 331331051 | C18: Drilling | D18: 13-5/8" BOP Stack Recertification | E18: Third party | F18: 693364 | G18: =F18*87 -> 60322668 | K18: =693364+48672 -> 742036 | N18: =H18*0.27+I18+J18*0.01149+K18+L18+M18 -> 742036 | O18: =F18-N18 -> -48672 | P18: RDDPL/BO/2526/00144 RDDPL/BO/2526/00010 | Q18: RDDPL/IPO/2526/00127 RDDPL/IPO/2526/00036 | R18: CS- CAMERON SNG Cost considered as per CS value, cost may increase post D&I
A19: 14 | B19: 331331021 | C19: Drilling | D19: 21-1/4" BOP Stack Recertification | E19: Third party | F19: 621572 | G19: =F19*87 -> 54076764 | K19: 621752 | N19: =H19*0.27+I19+J19*0.01149+K19+L19+M19 -> 621752 | O19: =F19-N19 -> -180 | R19: CS- CAMERON SNG Cost considered as per CS value, cost may increase post D&I
A20: 15 | B20: 312312011 | C20: Drilling | D20: Eaton Dynamic brake/Emergency brake inspection and certification | E20: OEM/API | G20: =F20*87 -> 0 | N20: =H20*0.27+I20+J20*0.01149+K20+L20+M20 -> 0 | O20: =F20-N20 -> 0
A21: 16 | B21: 325053001 | C21: Drilling | D21: Mud Pumps - Pulsation Dampeners & Relief Valves | E21: Rig Crew/Third Party | F21: =10000+25000 -> 35000 | G21: =F21*87 -> 3045000 | I21: 1843.82 | K21: =31031.88+567 -> 31598.88 | N21: =H21*0.27+I21+J21*0.01149+K21+L21+M21 -> 33442.7 | O21: =F21-N21 -> 1557.3 | P21: RDDPL/BO/2526/00178 RJPSL/BO/2526/00234 RJPSL/BO/2526/00047 RDDPL/BO/2526/00085 | Q21: RDDPL/IPO/2526/00139 RJPSL/IPO/2526/00305 RJPSL/IPO/2526/00046 RDDPL/IPO/2526/00077 | R21: Estimated
A22: 17 | B22: 337047001 | C22: Drill floor | D22: BOP Test Pump refurbishment | E22: Rig Crew/Third Party | F22: 15000 | G22: =F22*87 -> 1305000 | H22: =3736+672+2946+174+270 -> 7798 | I22: =4736+3828 -> 8564 | J22: 55022 | N22: =H22*0.27+I22+J22*0.01149+K22+L22+M22 -> 11301.663 | O22: =F22-N22 -> 3698.3372 | P22: RJPSL/BO/2526/00378 RJPDD/BO/2526/00280 RJPSL/BO/2526/00378 RJPSL/BO/2526/00383 RJPSL/BO/2526/00362 RJPSL/BO/2526/00059, RJPSL/BO/2526/00253 | Q22: RJPSL/IPO/2627/00010 RJPDD/LPO/2526/00057 RJPSL/IPO/2526/00311 RJPSL/IPO/2526/00296 RJPSL/IPO/2526/00268 RJPSL/IPO/2526/00241 RJPSL/IPO/2526/00134, RJPSL/IPO/2526/00157 | R22: Estimated
A23: 18 | C23: Drill floor | D23: Wireline Unit - Inhouse maintenance | E23: Rig Crew/Third Party | F23: 5000 | G23: =F23*87 -> 435000 | N23: =H23*0.27+I23+J23*0.01149+K23+L23+M23 -> 0 | O23: =F23-N23 -> 5000 | R23: Estimated
A24: 19 | B24: 346348005 | C24: Drill floor | D24: Spinner - Overhauling | E24: Rig Crew/Third Party | F24: 4000 | G24: =F24*87 -> 348000 | N24: =H24*0.27+I24+J24*0.01149+K24+L24+M24 -> 0 | O24: =F24-N24 -> 4000 | R24: Estimated
A25: 20 | C25: Drill floor | D25: Inside BOP Valves - Inspection & Pressure Testing (3-1/2" , 5", 5-1/2") - with Spares | E25: Rig Crew/Third Party | F25: 25000 | G25: =F25*87 -> 2175000 | K25: 60462 | N25: =H25*0.27+I25+J25*0.01149+K25+L25+M25 -> 60462 | O25: =F25-N25 -> -35462 | P25: RDDPL/BO/2526/00088 | Q25: RDDPL/IPO/2526/00086 | R25: Estimated
A26: 21 | C26: Drill floor | D26: FOSVs - Inspection & Pressure Testing (3-1/2 ), with Spares | E26: Rig Crew/Third Party | F26: 10000 | G26: =F26*87 -> 870000 | N26: =H26*0.27+I26+J26*0.01149+K26+L26+M26 -> 0 | O26: =F26-N26 -> 10000 | R26: Estimated
D27: Cup tester | F27: 2400 | G27: =F27*87 -> 208800 | N27: =H27*0.27+I27+J27*0.01149+K27+L27+M27 -> 0 | O27: =F27-N27 -> 2400 | R27: Moulded cup as the codition is deteriorated
A28: 22 | B28: 317077001 | C28: Drill floor | D28: Pile Hammer procurement/ Transfer from sister rig | G28: =F28*87 -> 0 | N28: =H28*0.27+I28+J28*0.01149+K28+L28+M28 -> 0 | O28: =F28-N28 -> 0
A29: 23 | B29: 328053073 | C29: Drill floor | D29: C&K Hoses, Rotary Hoses - Certification /Pressure test with remedial under API 16C & API 7K | E29: Procurement of Choke and kill hoses as per operational requirements | F29: 400000 | G29: =F29*87 -> 34800000 | H29: 25200 | I29: =3808+78425 -> 82233 | N29: =H29*0.27+I29+J29*0.01149+K29+L29+M29 -> 89037 | O29: =F29-N29 -> 310963 | P29: RJPSL/BO/2526/00479 RJPSL/BO/2526/00056 | Q29: RJPSL/IPO/2526/00337 RJPSL/IPO/2526/00104 | R29: Ref: JINDAL STAR DD-23 -Hoses not replaced in the last 6 years. Replacement of Min 6 hoses considered -Added additional $1,00,000 considering increase in cost
A30: 24 | B30: 336336001/325326001 | C30: Well Control | D30: Standpipe Manifold Choke & Kill Manifold valves and Cement Manifold - Recertification | E30: Third Party | F30: =181780+79408 -> 261188 | G30: =F30*87 -> 22723356 | J30: 15600 | K30: =142654+154490+77266+12990 -> 387400 | N30: =H30*0.27+I30+J30*0.01149+K30+L30+M30 -> 387579.24 | O30: =F30-N30 -> -126391.24 | P30: RJPDD/BO/2526/00295 RDDPL/BO/2526/00189 RDDPL/BO/2526/00115 RDDPL/BO/2526/00080 RDDPL/BO/2526/00064 | Q30: RJPDD/LPO/2627/00002 RDDPL/IPO/2526/00143 RDDPL/IPO/2526/00090 RDDPL/IPO/2526/00022 RDDPL/IPO/2526/00058 | R30: CAT IV Ref WOM : JULY 2025 Mud / standpipe manifold - 41,524+21373 Cement Manifoild : 2859+9732 Choke and kill manifold:33275+48303 Hydraulic and manual chokes : 84122 Contingency: 20000
A31: 25 | B31: 332332001/332335001 | C31: Well Control | D31: BOP Control System - Re-Certification - Hydrotest of accumulator bottles,Pressure Vessels, Replacement of bladers and Recertification of Hydraulic hoses and HP lines | E31: Third Party | F31: 500000 | G31: =F31*87 -> 43500000 | H31: =39600 + 35625+4944 -> 80169 | I31: =20050+17343 -> 37393 | K31: =63007 -> 63007 | N31: =H31*0.27+I31+J31*0.01149+K31+L31+M31 -> 122045.63 | O31: =F31-N31 -> 377954.37 | P31: RJPSL/BO/2526/00437 RJPSL/BO/2526/00353 RJPSL/BO/2526/00258 RDDPL/BO/2526/00123 RJPSL/BO/2526/00105, RJPSL/BO/2526/00109, RJPSL/BO/2526/00207, RJPSL/BO/2526/00271 | Q31: RJPSL/IPO/2526/00307 RJPSL/IPO/2526/00260 RJPSL/IPO/2526/00253 RDDPL/IPO/2526/00085 RJPSL/IPO/2526/00075, RJPSL/IPO/2526/00103, RJPSL/IPO/2526/00146, RJPSL/IPO/2526/00195 | R31: 5 yearly certification as per API 16D 3rd edition requirement as per OISD 174 Estimated
A32: 26 | C32: Well Control | D32: Adapter, Spools, Risers, DSA, Procurement Recertification | E32: Third Party | G32: =F32*87 -> 0 | N32: =H32*0.27+I32+J32*0.01149+K32+L32+M32 -> 0 | O32: =F32-N32 -> 0 | R32: Considered in Ann X Sr#26
A33: 27 | C33: Well Control | D33: BOP Side Outlets valves Recertification | E33: Third Party | F33: 30000 | G33: =F33*87 -> 2610000 | I33: 3155.6 | K33: =1445+31860 -> 33305 | N33: =H33*0.27+I33+J33*0.01149+K33+L33+M33 -> 36460.6 | O33: =F33-N33 -> -6460.6 | P33: RDDPL/BO/2526/00170 RJPSL/BO/2526/00120 RDDPL/BO/2526/00136 | Q33: RDDPL/IPO/2526/00134 RJPSL/IPO/2526/00150 RDDPL/IPO/2526/00118 | R33: Estimated
A34: 28 | C34: BOP RAMs | D34: Inventory of BOP RAMs & elastomers to be checked & recertified. | E34: Third Party | F34: 100000 | G34: =F34*87 -> 8700000 | I34: 12800 | K34: 82687 | N34: =H34*0.27+I34+J34*0.01149+K34+L34+M34 -> 95487 | O34: =F34-N34 -> 4513 | P34: RJPSL/BO/2526/00178 RDDPL/BO/2526/00071, RDDPL/BO/2526/00106, RDDPL/BO/2526/00098 | Q34: RJPSL/IPO/2526/00121 RDDPL/IPO/2526/00068, RDDPL/IPO/2526/00076, RDDPL/IPO/2526/00095 | R34: Estimated
A35: 29 | C35: HP Hoses | D35: HP Hose recertification (14 No.) and repalcement if rejected - Accounted in Hose Register | E35: Third Party | G35: =F35*87 -> 0 | K35: 162.5 | N35: =H35*0.27+I35+J35*0.01149+K35+L35+M35 -> 162.5 | O35: =F35-N35 -> -162.5 | P35: RDDPL/BO/2526/00076 | Q35: RDDPL/IPO/2526/00066 | R35: Considered in Sr#24
A36: 30 | C36: Mud System | D36: Solid control system - Shale shakers (3 No), Desander, Desilter , Mud cleaner,Mud agitator Degasser,Gumbo shaker, Shale shaker baskets & gates | E36: Third party/ Rig crew | F36: 250000 | G36: =F36*87 -> 21750000 | H36: =9831+3796 -> 13627 | K36: =98384+4000 -> 102384 | N36: =H36*0.27+I36+J36*0.01149+K36+L36+M36 -> 106063.29 | O36: =F36-N36 -> 143936.71 | P36: RJPSL/BO/2526/00400 RDDPL/BO/2526/00176 RJPSL/BO/2526/00108, RJPSL/BO/2526/00206, RJPSL/BO/2526/00269, RJPSL/BO/2526/00265 RDDPL/BO/2526/00026, RDDPL/BO/2526/00027, RDDPL/BO/2526/00061, RDDPL/BO/2526/00086 | Q36: RJPSL/IPO/2526/00329 RDDPL/IPO/2526/00130 RJPSL/IPO/2526/00087, RJPSL/IPO/2526/00177, RJPSL/IPO/2526/00180, RJPSL/IPO/2526/00197 RDDPL/IPO/2526/00008, RDDPL/IPO/2526/00009, RDDPL/IPO/2526/00070, RDDPL/IPO/2526/00075 | R36: Overhaul -Estimated Shale Shakers, Cutting dryer, Augers for Dryer & Shakers, Feed Pumps, Centrifugfes, Degasser, Vaccum compressor, Poor Buoy
B37: 326342001 | E37: Shale Shaker basket | F37: =55000*2 -> 110000 | G37: =F37*87 -> 9570000 | K37: 110000 | N37: =H37*0.27+I37+J37*0.01149+K37+L37+M37 -> 110000 | O37: =F37-N37 -> 0 | P37: RDDPL/BO/2526/00134 | Q37: RDDPL/IPO/2526/00110 | R37: Ref Star DD New Basket cost from Import, USD 55000
A38: 31 | B38: 326025001 | C38: Mud System | D38: Centrifuges-Major Overhaul required | E38: Third party | F38: 60000 | G38: =F38*87 -> 5220000 | J38: 18000 | K38: 5113.6 | N38: =H38*0.27+I38+J38*0.01149+K38+L38+M38 -> 5320.42 | O38: =F38-N38 -> 54679.58 | P38: RJPDD/BO/2526/00273 RDDPL/BO/2526/00063 | Q38: RJPDD/LPO/2526/00052 RDDPL/IPO/2526/00029 | R38: Considered in Sr#30
A39: 32 | B39: 324026001/324026001 | C39: Mud System | D39: Mud tank Agitators and Mud guns- Overhauling & need to replace some off fan blades | G39: =F39*87 -> 0 | N39: =H39*0.27+I39+J39*0.01149+K39+L39+M39 -> 0 | O39: =F39-N39 -> 0 | R39: Considered in Sr#30
A40: 33 | B40: 324 | C40: Mud System | D40: Mixing Hopper & Mixer-Overhauling & Testing | E40: Rig Crew | G40: =F40*87 -> 0 | N40: =H40*0.27+I40+J40*0.01149+K40+L40+M40 -> 0 | O40: =F40-N40 -> 0 | R40: Considered in Sr#30
...

Sheet Ann VII-Mech
A1: BUDGETED EXPENSES FOR JINDAL PIONEER RECERTIFICATION & MISCELLANEOUS SERVICES- ANNEXURE VII
A2: G | C2: MECHANICAL
A3: Sr. No. | B3: Material Code | C3: Area | D3: DEPARTMENT / JOB DESCRIPTION | E3: WORK TO BE CARRIED OUT BY | F3: Budgetory Cost (USD) | G3: BUDGETORY COST (INR) | H3: Actual Local Cost (AED) | I3: Actual Local Cost (USD) | J3: Actual Local Cost (INR) | K3: Actual Cost Import (USD) | L3: Projected Cost | M3: Actucal Total Cost (USD) | N3: Surplus/Exceeded | O3: MR NO | P3: PO NO | Q3: Remarks
A4: 1 | B4: 65160000 | C4: Engine | D4: Engine MOH- 3 engines | E4: Third party | F4: =(191999*3)+150000+60000 -> 785997 | G4: =F4*87 -> 68381739 | H4: 4637 | J4: 12404 | K4: =254422.63*3 + 144071.18 +92834+5912+10904.9+1769+5262 -> 1024021 | M4: =H4*0.27+I4+J4*0.01149+K4 -> 1025415.5 | N4: =F4-M4 -> -239418.48 | O4: RJPDD/BO/2526/00301 RDDPL/BO/2526/00179 RDDPL/BO/2526/00174 RDDPL/BO/2526/00156 RJPSL/BO/2526/00290 RDDPL/BO/2526/00034, RDDPL/BO/2526/00011, RDDPL/BO/2526/00012, RDDPL/BO/2526/00013, RDDPL/BO/2526/00014, RDDPL/BO/2526/00127 RDDPL/BO/2526/00152 | P4: RJPDD/BO/2526/00301 RDDPL/IPO/2526/00146 RDDPL/IPO/2526/00135 RDDPL/IPO/2526/00129 RJPSL/IPO/2526/00214 RDDPL/IPO/2526/00020, RDDPL/IPO/2526/00037, RDDPL/IPO/2526/00038, RDDPL/IPO/2526/00039, RDDPL/IPO/2526/00050, RDDPL/IPO/2526/00109 RDDPL/IPO/2526/00117 | Q4: PO- ENERIA MOH spare cost Considered for Engines- #1 ,#2 , #4- $191999/Engine MOH spare cost considred for Engine - #3 and #5- $75000/Engine Service cost - $60000 (5 engines)
A5: 2 | B5: 651620020 | C5: Cooling system | D5: Engine radiator System overhaul | E5: Rig crew | F5: 50000 | I5: =63429+6036 -> 69465 | M5: =H5*0.27+I5+J5*0.01149+K5 -> 69465 | N5: =F5-M5 -> -19465 | O5: RJPSL/BO/2526/00411 RJPSL/BO/2526/00041, RJPSL/BO/2526/00040 | P5: RJPSL/IPO/2526/00277 RJPSL/IPO/2526/00042, RJPSL/IPO/2526/00110 | Q5: ESTIMATED
A6: 3 | B6: 651620011 | C6: Air system | D6: Need to be overhaul and General service all 3 Air compressor | E6: Rig crew | F6: 100000 | H6: 1862 | K6: 29966.17 | M6: =H6*0.27+I6+J6*0.01149+K6 -> 30468.91 | N6: =F6-M6 -> 69531.09 | O6: RJPSL/BO/2526/00208 RDDPL/BO/2526/00104 | P6: RJPSL/IPO/2526/00132 RDDPL/IPO/2526/00071 | Q6: ESTIMATED
A7: 4 | B7: 651620011 | C7: Air system | D7: Air dryers need to be overhaul(service air dryer & Bulk air dryer) | E7: Rig crew | F7: 25000 | H7: 6500 | K7: 8250 | M7: =H7*0.27+I7+J7*0.01149+K7 -> 10005 | N7: =F7-M7 -> 14995 | O7: RJPSL/BO/2526/00505 RDDPL/BO/2526/00121 | P7: RJPSL/IPO/2627/00012 RDDPL/IPO/2526/00141 | Q7: ESTIMATED
A8: 5 | B8: 651620011 | C8: Air system | D8: Cold Start Compressor - Overhauling & Testing | E8: Rig crew | F8: 10000 | M8: =H8*0.27+I8+J8*0.01149+K8 -> 0 | N8: =F8-M8 -> 10000 | Q8: ESTIMATED
A9: 6 | C9: Auxiliary Pumps | D9: All the pumps(Mud mixing, mud charging, fire /sea water/Drill water/foam & deluge pump , foam pump , Degasser, Desilter, mud clener pumps, Trip tank pumps, Base oil & break cooling pumps, fuel service & transfer pumps ,Brine Pump,speck pumps need to service & overhual | E9: Rig Crew/Third party | F9: 50000 | H9: =1298+1815 -> 3113 | K9: =36072+80652+123 -> 116847 | M9: =H9*0.27+I9+J9*0.01149+K9 -> 117687.51 | N9: =F9-M9 -> -67687.51 | O9: RDDPL/BO/2526/00165 RJPSL/BO/2526/00489 RDDPL/BO/2526/00160 RJPSL/BO/2526/00115 RDDPL/BO/2526/00082, RDDPL/BO/2526/00050, RDDPL/BO/2526/00070, RDDPL/BO/2526/00069 | P9: RDDPL/IPO/2526/00144 RJPSL/IPO/2526/00354 RDDPL/IPO/2526/00119 RJPSL/IPO/2526/00091 RDDPL/IPO/2526/00023, RDDPL/IPO/2526/00033, RDDPL/IPO/2526/00063, RDDPL/IPO/2526/00069 | Q9: ESTIMATED
A10: 7 | C10: Water maker | D10: Water Maker - Need to be overhaul, service and remedial spare parts | E10: Rig crew | F10: 50000 | H10: 144 | K10: =3496.27+2520 -> 6016.27 | M10: =H10*0.27+I10+J10*0.01149+K10 -> 6055.15 | N10: =F10-M10 -> 43944.85 | O10: RDDPL/BO/2526/00194 RJPSL/BO/2526/00179 RDDPL/BO/2526/00068 | P10: RDDPL/IPO/2526/00154 RJPSL/IPO/2526/00143 RDDPL/IPO/2526/00067 | Q10: ESTIMATED
A11: 8 | B11: 803047001 | C11: Deck equipment | D11: Bilge system pumps - Overhaul & Testing | E11: Rig crew | F11: 25000 | H11: 2730 | M11: =H11*0.27+I11+J11*0.01149+K11 -> 737.1 | N11: =F11-M11 -> 24262.9 | O11: RJPSL/BO/2526/00020 | P11: RJPSL/IPO/2526/00023 | Q11: ESTIMATED
A12: 9 | B12: 702045001 | C12: Deck equipment | D12: Diesel Oil Purifier - Overhaul/ one Drive motor procurement to be done. | E12: Rig crew | F12: 25000 | K12: 2245 | M12: =H12*0.27+I12+J12*0.01149+K12 -> 2245 | N12: =F12-M12 -> 22755 | O12: RDDPL/BO/2526/00057 | P12: RDDPL/IPO/2526/00032 | Q12: ESTIMATED
A13: 10 | B13: 721047001 | C13: Deep well | D13: Deep Well Pumps , Deep well manifold & strainer modification by 3rd party - Overhaul & Testing | E13: Third party | F13: 10000 | H13: 4320 | K13: 7049.85 | M13: =H13*0.27+I13+J13*0.01149+K13 -> 8216.25 | N13: =F13-M13 -> 1783.75 | O13: RDDPL/BO/2526/00140 RJPSL/BO/2526/00246 | P13: RDDPL/IPO/2526/00126 RJPSL/IPO/2526/00174 | Q13: ESTIMATED
D14: New purchase of 2 deep well pumps | M14: =H14*0.27+I14+J14*0.01149+K14 -> 0 | N14: =F14-M14 -> 0 | Q14: ESTIMATED
A15: 12 | B15: 444047001 | C15: Deck equipment | D15: High Pressure Washers- Overhauling & Testing | E15: Rig crew | F15: 10000 | H15: 8785 | J15: 850000 | M15: =H15*0.27+I15+J15*0.01149+K15 -> 12138.45 | N15: =F15-M15 -> -2138.45 | O15: RJPDD/BO/2526/00210 RJPSL/BO/2526/00116 | P15: RJPDD/LPO/2526/00030 RJPSL/IPO/2526/00092 | Q15: ESTIMATED
A16: 13 | B16: 445074001 | C16: Deck equipment | D16: Garbage Compactor - Overhaul & Testing | E16: Rig crew | F16: 10000 | M16: =H16*0.27+I16+J16*0.01149+K16 -> 0 | N16: =F16-M16 -> 10000 | Q16: ESTIMATED
A17: 14 | C17: Deck equipment | D17: Macerator - Overhaul & Testing | E17: Rig crew | F17: 10000 | K17: 15834.74 | M17: =H17*0.27+I17+J17*0.01149+K17 -> 15834.74 | N17: =F17-M17 -> -5834.74 | O17: RDDPL/BO/2526/00116 | P17: RDDPL/IPO/2526/00103 | Q17: ESTIMATED
A18: 15 | B18: 301301001 | C18: Drill floor | D18: Casing Stabbing Board - need to be service,recertified. | E18: Rig crew | F18: 25000 | H18: 8727 | M18: =H18*0.27+I18+J18*0.01149+K18 -> 2356.29 | N18: =F18-M18 -> 22643.71 | O18: RJPSL/BO/2526/00319 | P18: RJPSL/IPO/2526/00223 | Q18: ESTIMATED
A19: 16 | B19: 385 | C19: Drill floor | D19: Main HPU - need to be service, replace all hydrulic control hoses,replace heat echanger assy, | E19: Rig Crew | F19: 50000 | K19: 6954 | M19: =H19*0.27+I19+J19*0.01149+K19 -> 6954 | N19: =F19-M19 -> 43046 | O19: RDDPL/BO/2526/00112, RDDPL/BO/2526/00112 | P19: RDDPL/IPO/2526/00087, RDDPL/IPO/2526/00088 | Q19: ESTIMATED
A20: 17 | B20: 312071001 | C20: Drill floor | D20: Drawwork Air Intensifier - need to be overhauled | E20: Rig Crew | F20: 50000 | K20: 18492.42 | M20: =H20*0.27+I20+J20*0.01149+K20 -> 18492.42 | N20: =F20-M20 -> 31507.58 | O20: RDDPL/BO/2526/00062 | P20: RDDPL/IPO/2526/00030 | Q20: ESTIMATED
A21: 18 | B21: 342349001 | C21: Drill floor | D21: Cathead - need to be overhaul hydraulic cylinders | E21: Rig crew | F21: 50000 | H21: 2561 | K21: 15770 | M21: =H21*0.27+I21+J21*0.01149+K21 -> 16461.47 | N21: =F21-M21 -> 33538.53 | O21: RJPSL/BO/2526/00111 RDDPL/BO/2526/00102, RDDPL/BO/2526/00125 | P21: RJPSL/IPO/2526/00088 RDDPL/IPO/2526/00061, RDDPL/IPO/2526/00105 | Q21: ESTIMATED
A22: 19 | C22: Drill floor | D22: Hydraulic & Pnuematic Hoses( BOP Hoist etc) - Inspection & Replacement | E22: Rig crew/Third Party | F22: 50000 | H22: =41305.02+21774 -> 63079.02 | I22: 4800 | K22: 2419.46 | M22: =H22*0.27+I22+J22*0.01149+K22 -> 24250.795 | N22: =F22-M22 -> 25749.205 | O22: RJPSL/BO/2526/00350 RJPSL/BO/2526/00338 RJPSL/BO/2526/00242 RDDPL/BO/2526/00119 | P22: RJPSL/IPO/2526/00283 RJPSL/IPO/2526/00273 RJPSL/IPO/2526/00263 RDDPL/IPO/2526/00089 | Q22: ESTIMATED
A23: 20 | B23: 365042001/365042003 | C23: Hoisting | D23: Utility Winches , manriding winch including Derrick Winch - Overhauling | E23: Third party | M23: =H23*0.27+I23+J23*0.01149+K23 -> 0 | N23: =F23-M23 -> 0 | Q23: Considered in Annexure VI SR no- 46
A24: 21 | B24: 365042012 | C24: Hoisting | D24: Manrider Winches - Overhauling | M24: =H24*0.27+I24+J24*0.01149+K24 -> 0 | N24: =F24-M24 -> 0 | Q24: Considered in Annexure VI SR no- 46
A25: 22 | B25: 36404201 | C25: Hoisting | D25: BOP hoist overhaul and load test Replace all Air supply hoses & control lines hoses | E25: Third party | F25: 100000 | H25: =5774+26077.5 -> 31851.5 | K25: 44477 | M25: =H25*0.27+I25+J25*0.01149+K25 -> 53076.905 | N25: =F25-M25 -> 46923.095 | O25: RJPSL/BO/2526/00355 RJPSL/BO/2526/00388 RDDPL/BO/2526/00105, RDDPL/BO/2526/00126 | P25: RJPSL/IPO/2526/00284 RJPSL/IPO/2526/00265 RDDPL/IPO/2526/00078, RDDPL/IPO/2526/00094 | Q25: ESTIMATED
A26: 23 | B26: 3610 | C26: Deck Crane | D26: Visually inspection/Overhaul of all winch gear boxes- Slew, Luff, Boom | E26: Third party | F26: 100000 | M26: =H26*0.27+I26+J26*0.01149+K26 -> 0 | N26: =F26-M26 -> 100000 | Q26: ESTIMATED
A27: 24 | B27: 803025001 | C27: Mechanical | D27: OWS - Overhauling | E27: Rig crew | F27: 25000 | H27: 9695 | M27: =H27*0.27+I27+J27*0.01149+K27 -> 2617.65 | N27: =F27-M27 -> 22382.35 | O27: RJPSL/BO/2526/00194, RJPSL/BO/2526/00225 | P27: RJPSL/IPO/2526/00123, RJPSL/IPO/2526/00126 | Q27: ESTIMATED
A28: 25 | B28: 582040001 | C28: Mechanical | D28: Sewage Treatment - Overhauling required one aeration blower required and remedial spares required | E28: Rig crew | F28: 25000 | H28: 3680 | K28: =11231+19227.23 -> 30458.23 | M28: =H28*0.27+I28+J28*0.01149+K28 -> 31451.83 | N28: =F28-M28 -> -6451.83 | O28: RJPSL/BO/2526/00280 RDDPL/BO/2526/00107, RDDPL/BO/2526/00107, RDDPL/BO/2526/00122 | P28: RJPSL/IPO/2526/00184 RDDPL/IPO/2526/00081, RDDPL/IPO/2526/00082, RDDPL/IPO/2526/00100 | Q28: ESTIMATED
A29: 26 | C29: Mechanical | D29: Sanitary System- Overhauling required and remedial spares required | E29: Rig Crew/Third party | F29: 25000 | H29: 4165 | M29: =H29*0.27+I29+J29*0.01149+K29 -> 1124.55 | N29: =F29-M29 -> 23875.45 | O29: RJPSL/BO/2526/00278 | P29: RJPSL/IPO/2526/00183 | Q29: ESTIMATED
A30: 27 | C30: Mechanical | D30: Fire pumps- complete overhaul | E30: Third party | F30: 25000 | H30: =2700+500 -> 3200 | M30: =H30*0.27+I30+J30*0.01149+K30 -> 864 | N30: =F30-M30 -> 24136 | O30: RJPSL/BO/2526/00433 RJPSL/BO/2526/00299 | P30: RJPSL/IPO/2526/00295 RJPSL/IPO/2526/00249 | Q30: ESTIMATED
A31: 28 | C31: Mechanical | D31: Potable Water System - Overhauling | E31: Rig crew | F31: 25000 | H31: 3087 | I31: 7825.56 | K31: 12690 | M31: =H31*0.27+I31+J31*0.01149+K31 -> 21349.05 | N31: =F31-M31 -> 3650.95 | O31: RJPSL/BO/2526/00216 RJPSL/BO/2526/00337 RDDPL/BO/2526/00059 | P31: RJPSL/IPO/2526/00278 RJPSL/IPO/2526/00255 RDDPL/IPO/2526/00027 | Q31: ESTIMATED
A32: 29 | B32: 196062005 | C32: Mechanical | D32: Tools/Fittings/Consumables/Machining equipments | E32: Third party | F32: 50000 | H32: =100707+194+2580 -> 103481 | I32: 20979 | J32: 618188 | K32: 993 | M32: =H32*0.27+I32+J32*0.01149+K32 -> 57014.85 | N32: =F32-M32 -> -7014.8501 | O32: RJPSL/BO/2526/00396 RJPSL/BO/2526/00329 RJPSL/BO/2526/00295 RJPDD/BO/2526/00186, RJPDD/BO/2526/00188, RJPDD/BO/2526/00239, RJPDD/BO/2526/00247 RDDPL/BO/2526/00025 RJPSL/BO/2526/00007, RJPSL/BO/2526/00018, RJPSL/BO/2526/00024, RJPSL/BO/2526/00030, RJPSL/BO/2526/00042, RJPSL/BO/2526/00060, RJPSL/BO/2526/00063, RJPSL/BO/2526/00102, RJPSL/BO/2526/00104, RJPSL/BO/2526/00124, RJPSL/BO/2526/00169, RJPSL/BO/2526/00122, RJPSL/BO/2526/00171, RJPSL/BO/2526/00186, RJPSL/BO/2526/00180, RJPSL/BO/2526/00172, RJPSL/BO/2526/00205, RJPSL/BO/2526/00172, RJPSL/BO/2526/00183, RJPSL/BO/2526/00291, RJPSL/BO/2526/00286 | P32: RJPSL/IPO/2526/00266 RJPSL/IPO/2526/00252 RJPSL/IPO/2526/00247 RJPDD/LPO/2526/00005, RJPDD/LPO/2526/00007, RJPDD/LPO/2526/00029, RJPDD/LPO/2526/00032 RDDPL/IPO/2526/00052 RJPSL/IPO/2526/00007, RJPSL/IPO/2526/00022, RJPSL/IPO/2526/00028, RJPSL/IPO/2526/00033, RJPSL/IPO/2526/00043, RJPSL/IPO/2526/00052, RJPSL/IPO/2526/00055, RJPSL/IPO/2526/00074, RJPSL/IPO/2526/00084, RJPSL/IPO/2526/00095, RJPSL/IPO/2526/00109, RJPSL/IPO/2526/00111, RJPSL/IPO/2526/00112, RJPSL/IPO/2526/00116, RJPSL/IPO/2526/00122, RJPSL/IPO/2526/00129, RJPSL/IPO/2526/00131, RJPSL/IPO/2526/00139, RJPSL/IPO/2526/00161, RJPSL/IPO/2526/00202, RJPSL/IPO/2526/00203 | Q32: ESTIMATED
A33: Total | F33: =SUM(F4:F32) -> 1760997 | G33: =SUM(G4:G32) -> 68381739 | M33: =SUM(M4:M32) -> 1534282.4 | N33: =F33-M33 -> 226714.6

Sheet Ann VIII-Elec
A1: BUDGETED EXPENSES FOR JINDAL PIONEER RECERTIFICATION & MISCELLANEOUS SERVICES -ANNEXURE IX
A2: H | B2: Electrical and Power Plant
A3: Sr. No. | B3: Material Code | C3: Area | D3: DEPARTMENT / JOB DESCRIPTION | E3: WORK TO BE CARRIED OUT BY | F3: Budgetory Cost (USD) | G3: BUDGETORY COST (INR) | H3: Actual cost Local (AED) | I3: Actual cost Local (USD) | J3: Actual cost Local (INR) | K3: Actual cost Import (USD) | L3: VOR (USD) | M3: Projected Cost | N3: Actucal Total Cost (USD) | O3: Surplus/Exceeded | P3: MR NO | Q3: PO NO | R3: Remarks
A4: 1 | B4: 651600000 | C4: Alternators | D4: NOV alternator - 5nos, (Overhauling) | E4: Third party | F4: 50000 | G4: =F4*87 -> 4350000 | H4: =136391+5300+8600 -> 150291 | J4: =160000+46600 -> 206600 | K4: 5556 | N4: =H4*0.27+I4+J4*0.01149+K4+L4 -> 48508.404 | O4: =F4-N4 -> 1491.596 | P4: RJPSL/BO/2526/00458 RJPDD/BO/2526/00237 RJPDD/BO/2526/00227 RJPSL/BO/2526/00322 RDDPL/BO/2526/00096, RDDPL/BO/2526/00110 RJPSL/BO/2526/00039, RJPSL/BO/2526/00223, RJPSL/BO/2526/00254 | Q4: RJPSL/IPO/2526/00321 RJPDD/LPO/2526/00040 RJPDD/LPO/2526/00040 RJPSL/IPO/2526/00222 RDDPL/IPO/2526/00083, RDDPL/IPO/2526/00084 RJPSL/IPO/2526/00040, RJPSL/IPO/2526/00128, RJPSL/IPO/2526/00191 | R4: Ref: Quote from WWPS
A5: 2 | B5: 325325001 | C5: Mud Pumps | D5: Main Motors(6 nos) and auxilary motors- (Overhauling) | E5: Third party | F5: 100000 | H5: =2500 -> 2500 | I5: 129935 | K5: 3941.88 | N5: =H5*0.27+I5+J5*0.01149+K5+L5 -> 134551.88 | O5: =F5-N5 -> -34551.88 | P5: RJPSL/BO/2526/00465 RDDPL/BO/2526/00120 RJPSL/BO/2526/00038, RJPSL/BO/2526/00112, RJPSL/BO/2526/00233, RJPSL/BO/2526/00224 | Q5: RJPSL/IPO/2526/00334 RDDPL/IPO/2526/00080 RJPSL/IPO/2526/00039, RJPSL/IPO/2526/00089, RJPSL/IPO/2526/00193, RJPSL/IPO/2526/00194 | R5: Considered in Sr no 2
A6: 3 | B6: 312081001 | C6: Drawworks | D6: Main Motors-( 3nos) and auxilary motors Overhauling & DWS Brake cooling Flow issue need to rectify . | E6: Third party | H6: 10719.5 | N6: =H6*0.27+I6+J6*0.01149+K6+L6 -> 2894.265 | O6: =F6-N6 -> -2894.265 | P6: RJPSL/BO/2526/00222 | Q6: RJPSL/IPO/2526/00313 | R6: Considered in Sr no 2
A7: 4 | B7: 313314 | C7: Top Drive | D7: Main Motor & auxiliary motor - overhauling | E7: Third party | N7: =H7*0.27+I7+J7*0.01149+K7+L7 -> 0 | O7: =F7-N7 -> 0 | R7: Considered in Annexure VI Sr no 4
A8: 5 | B8: 313081011 | C8: Rotary table | D8: Main Motor & auxiliary motor - overhauling | E8: Third party | N8: =H8*0.27+I8+J8*0.01149+K8+L8 -> 0 | O8: =F8-N8 -> 0 | R8: Considered in Sr no 2
A9: 6 | B9: 311085001 | C9: Rig Sense | D9: Rig sense system need to be updated to latest version & all the sensor fault rectification and calibration by NOV. (Mud pit, trip tank level sensors, mud conductivity, density, temperature sensors and mud return flow sensor). | E9: Third party | F9: 120000 | K9: 115449.01 | N9: =H9*0.27+I9+J9*0.01149+K9+L9 -> 115449.01 | O9: =F9-N9 -> 4550.99 | P9: RDDPL/BO/2526/00128 | Q9: RDDPL/IPO/2526/00102 | R9: Ref-JE DD 25 $120000
A10: 7 | B10: 488 | C10: Jacking System | D10: Jacking system and need to carryout health check up (Motors, Brakes & Jacking MCC Panels). | E10: Third party | F10: 25000 | N10: =H10*0.27+I10+J10*0.01149+K10+L10 -> 0 | O10: =F10-N10 -> 25000 | R10: Estimated
A11: 8 | B11: 867090001 | C11: Variable frequeny Drives | D11: All the VFDs (Mud pump, Draw works and TDS/RT)need to carryout health check up . | E11: Third party | F11: 25000 | H11: =2450+2193 -> 4643 | N11: =H11*0.27+I11+J11*0.01149+K11+L11 -> 1253.61 | O11: =F11-N11 -> 23746.39 | P11: RJPSL/BO/2526/00324 RJPSL/BO/2526/00251 | Q11: RJPSL/IPO/2526/00360 RJPSL/IPO/2526/00207
A12: 9 | B12: 311084001 | C12: Amphion | D12: Amphion Integrated network system need to carryout healthcheckup and necessary trouble shooting if required | E12: Third party | F12: 25000 | N12: =H12*0.27+I12+J12*0.01149+K12+L12 -> 0 | O12: =F12-N12 -> 25000 | R12: Estimated
A13: 10 | B13: 871088/872088 | C13: Main & Emergency switchboard | D13: All the switchboard (PCR, E-Gen) main breakers health check-up and primary current injection test . | E13: Third party | F13: 25000 | H13: 1764.19 | K13: 8933 | L13: 14882 | N13: =H13*0.27+I13+J13*0.01149+K13+L13 -> 24291.331 | O13: =F13-N13 -> 708.6687 | P13: RJPSL/BO/2526/00214 RDDPL/BO/2526/00067, RDDPL/BO/2526/00129 | Q13: RJPSL/IPO/2526/00169 RDDPL/IPO/2526/00035, RDDPL/IPO/2526/00107 | R13: Estimated
A14: 11 | B14: 5710 | C14: HVAC | D14: All the HVAC, FAHU ,chiller freezer ,driller cabinunit health check-up , troubleshooting required | E14: Third party | F14: 125000 | H14: =350+180455+2700+3765+11024 -> 198294 | K14: =9940+209.2 -> 10149.2 | L14: 80926 | N14: =H14*0.27+I14+J14*0.01149+K14+L14 -> 144614.58 | O14: =F14-N14 -> -19614.58 | P14: RJPSL/BO/2526/00471 RJPSL/BO/2526/00464 RDDPL/BO/2526/00175 RJPSL/BO/2526/00301 RJPSL/BO/2526/00335 RJPSL/BO/2526/00288 | Q14: RJPSL/IPO/2627/00015 RJPSL/IPO/2526/00347 RDDPL/IPO/2526/00140 RJPSL/IPO/2526/00293 RJPSL/IPO/2526/00238 RJPSL/IPO/2526/00216 | R14: Estimated
A15: 12 | C15: Motors | D15: All the motors (Mud mixing, mud charging, fire pump motor, foam pump motor, drill floor HPU, cantilever skidding motor, Radiator motor, mud cutting dryer motor, PORT AFT & PORT FWD crane motor, shale shaker motor, Desander, Desilter, Degasser motor, Mud centrifuge motor, brake cooling motors, mud agitator motors, Air compressor motor, cement unit chemical mixing motors, Trip tank motor, All the life boat motors.) motors need to be inspect (health check-up) including Vibration Checks. | E15: Third party | F15: 100000 | H15: 14955 | K15: =4629+46994 -> 51623 | N15: =H15*0.27+I15+J15*0.01149+K15+L15 -> 55660.85 | O15: =F15-N15 -> 44339.15 | P15: RDDPL/BO/2526/00138 RJPSL/BO/2526/00196, RJPSL/BO/2526/00289 RDDPL/BO/2526/00054, RDDPL/BO/2526/00054, RDDPL/BO/2526/00090 | Q15: RDDPL/IPO/2526/00136 RJPSL/IPO/2526/00151, RJPSL/IPO/2526/00201 RDDPL/IPO/2526/00042, RDDPL/IPO/2526/00043, RDDPL/IPO/2526/00072 | R15: Estimated
A16: 13 | C16: Electrical | D16: Panel Meter calibration and certification | E16: Third party | F16: 10000 | K16: =521+412 -> 933 | N16: =H16*0.27+I16+J16*0.01149+K16+L16 -> 933 | O16: =F16-N16 -> 9067 | P16: RDDPL/BO/2526/00151 RDDPL/BO/2526/00151 | Q16: RDDPL/IPO/2526/00137 RDDPL/IPO/2526/00138 | R16: Estimated
A17: 14 | C17: Transformers | D17: 2000 KVA( 2no) AND 225 KVA(3 no) TRANSFORMER Inspection & health checkup | E17: Third party | F17: 10000 | L17: 5978 | N17: =H17*0.27+I17+J17*0.01149+K17+L17 -> 5978 | O17: =F17-N17 -> 4022 | R17: Estimated
A18: 15 | C18: Cementing unit & Batch mixer engine | D18: Data Monitoring system need to be Installed and Configure , Batch mixer engine starting issue Need to troubleshoot and rectify. | E18: Third party | F18: 40000 | N18: =H18*0.27+I18+J18*0.01149+K18+L18 -> 0 | O18: =F18-N18 -> 40000 | R18: Estimated
A19: 16 | B19: 421 | C19: Radio equipments | D19: Need to carryout health check UP & fault rectification , PROCREMENT | E19: Third party | F19: 10000 | H19: 2000 | I19: 1000 | J19: 66000 | N19: =H19*0.27+I19+J19*0.01149+K19+L19 -> 2298.34 | O19: =F19-N19 -> 7701.66 | P19: RJPDD/BO/2526/00271 RJPSL/BO/2526/00213 RJPSL/BO/2526/00036, RJPSL/BO/2526/00284 | Q19: RJPDD/LPO/2526/00056 RJPSL/IPO/2526/00256 RJPSL/IPO/2526/00037, RJPSL/IPO/2526/00189 | R19: Estimated
A20: 17 | B20: 867 | C20: Main UPS (35KVA) | D20: Main UPS need to be inspected and serviced | E20: Rig Crew | F20: 10000 | N20: =H20*0.27+I20+J20*0.01149+K20+L20 -> 0 | O20: =F20-N20 -> 10000 | R20: Estimated
A21: 18 | B21: 372056001 | C21: Burner boom | D21: Burner boom ignition system need to be serviced by inhouse and remedial spares | E21: Rig Crew | F21: 50000 | J21: 245000 | N21: =H21*0.27+I21+J21*0.01149+K21+L21 -> 2815.05 | O21: =F21-N21 -> 47184.95 | P21: RJPDD/BO/2526/00248 | Q21: RJPDD/LPO/2526/00031 | R21: Estimated
A22: 19 | B22: 332068001 | C22: BOP UPS (3.75 KVA) | D22: BOP Control unit UPS Batteries need to replace Existing batteries are expired already 07/2023. | E22: Rig Crew | F22: 10000 | H22: 3520 | N22: =H22*0.27+I22+J22*0.01149+K22+L22 -> 950.4 | O22: =F22-N22 -> 9049.6 | P22: RJPSL/BO/2526/00128 | Q22: RJPSL/IPO/2526/00108 | R22: Estimated
A23: 20 | B23: 196062002 | C23: Galley Equipments | D23: Galley equipment’s need to be inspected ( ice cube machine BER raised MR) | E23: Rig Crew | F23: 10000 | H23: =2855+4222+125 -> 7202 | N23: =H23*0.27+I23+J23*0.01149+K23+L23 -> 1944.54 | O23: =F23-N23 -> 8055.46 | P23: RJPSL/BO/2526/00255 RJPSL/BO/2526/00315 RJPSL/BO/2526/00048 | Q23: RJPSL/IPO/2526/00237 RJPSL/IPO/2526/00231 RJPSL/IPO/2526/00047 | R23: Estimated
A24: 21 | B24: 811 | C24: Fire & Gas System | D24: Fire & Gas system inspection and repair. | E24: Third party | F24: 25000 | H24: 4842 | J24: 568866 | K24: 8696 | N24: =H24*0.27+I24+J24*0.01149+K24+L24 -> 16539.61 | O24: =F24-N24 -> 8460.3897 | P24: RJPDD/BO/2526/00287 RJPSL/BO/2526/00507 RDDPL/BO/2526/00184 | Q24: RJPDD/LPO/2627/00003 RJPSL/IPO/2627/00014 RDDPL/IPO/2526/00150 | R24: Estimated
A25: 22 | B25: 425094 | C25: PAGA | D25: All the telephone inspection and repair. | E25: Third party | F25: 25000 | H25: 4604 | N25: =H25*0.27+I25+J25*0.01149+K25+L25 -> 1243.08 | O25: =F25-N25 -> 23756.92 | P25: RJPSL/BO/2526/00126 | Q25: RJPSL/IPO/2526/00114 | R25: Estimated
A26: 23 | B26: 821069001 | C26: Tank gauging system | D26: Tankgauging system PC not working in control room, need to rectify the issue. | E26: Third party | F26: 50000 | N26: =H26*0.27+I26+J26*0.01149+K26+L26 -> 0 | O26: =F26-N26 -> 50000 | R26: Estimated
A27: 24 | C27: General | D27: EX survey | E27: Third party | F27: 10000 | L27: 11090 | N27: =H27*0.27+I27+J27*0.01149+K27+L27 -> 11090 | O27: =F27-N27 -> -1090 | R27: Estimated
A28: 25 | C28: General | D28: Remedial action of EX survey | E28: Third party | F28: 30000 | H28: 1020 | K28: 1008 | N28: =H28*0.27+I28+J28*0.01149+K28+L28 -> 1283.4 | O28: =F28-N28 -> 28716.6 | P28: RDDPL/BO/2526/00171 RJPSL/BO/2526/00445 | Q28: RDDPL/IPO/2526/00147 RJPSL/IPO/2526/00344 | R28: Estimated
A29: 26 | C29: General | D29: Noise/DB survey | E29: Rig Crew | N29: =H29*0.27+I29+J29*0.01149+K29+L29 -> 0 | O29: =F29-N29 -> 0 | R29: Estimated
A30: 27 | C30: General | D30: Thermographic survey | E30: Rig Crew | N30: =H30*0.27+I30+J30*0.01149+K30+L30 -> 0 | O30: =F30-N30 -> 0 | R30: Estimated
A31: 28 | C31: General | D31: Lux Survey | E31: Rig Crew | N31: =H31*0.27+I31+J31*0.01149+K31+L31 -> 0 | O31: =F31-N31 -> 0 | R31: Estimated
A32: 29 | B32: 892085001 | C32: General | D32: General Rig lighting improvement | E32: Rig crew | F32: 100000 | H32: =18371+1908 -> 20279 | K32: =52231.3+3665+12065 -> 67961.3 | N32: =H32*0.27+I32+J32*0.01149+K32+L32 -> 73436.63 | O32: =F32-N32 -> 26563.37 | P32: RJPSL/BO/2526/00447 RDDPL/BO/2526/00142 RDDPL/BO/2526/00135 RJPSL/BO/2526/00084, RJPSL/BO/2526/00229, RJPSL/BO/2526/00212, RJPSL/BO/2526/00212 | Q32: RJPSL/IPO/2526/00358 RDDPL/IPO/2526/00125 RDDPL/IPO/2526/00104 RJPSL/IPO/2526/00077, RJPSL/IPO/2526/00138, RJPSL/IPO/2526/00160, RJPSL/IPO/2526/00162 | R32: Ref- JS DD -23 $100000
A33: 30 | B33: 4270 | C33: General | D33: Aviation warning lights, Navigation lights/Battery/ Replacement and remedial if required | E33: Rig crew/Third party | F33: 10000 | H33: 12060 | I33: 456.68 | J33: 40500 | K33: 2916.81 | N33: =H33*0.27+I33+J33*0.01149+K33+L33 -> 7095.035 | O33: =F33-N33 -> 2904.965 | P33: RJPDD/BO/2526/00079 RDDPL/BO/2526/00094 RJPSL/BO/2526/00089, RJPSL/BO/2526/00239 | Q33: RJPDD/LPO/2526/00003 RDDPL/IPO/2526/00091 RJPSL/IPO/2526/00079, RJPSL/IPO/2526/00080, RJPSL/IPO/2526/00155 | R33: Estimated
A34: 31 | C34: General | D34: Emergency lighting | E34: Rig crew | F34: 25000 | N34: =H34*0.27+I34+J34*0.01149+K34+L34 -> 0 | O34: =F34-N34 -> 25000 | R34: Estimated
A35: 32 | C35: General | D35: Electrical Tools, calibration of potable electric meters | E35: Third party | F35: 50000 | H35: =1411.7+3145.29+23010+605.52+1100+635.89+1891.55+11294+9450 -> 52543.95 | N35: =H35*0.27+I35+J35*0.01149+K35+L35 -> 14186.867 | O35: =F35-N35 -> 35813.133 | P35: RJPSL/BO/2526/00384 RJPSL/BO/2526/00006, RJPSL/BO/2526/00006, RJPSL/BO/2526/00015, RJPSL/BO/2526/00021, RJPSL/BO/2526/00219, RJPSL/BO/2526/00219, RJPSL/BO/2526/00218, RJPSL/BO/2526/00217 | Q35: RJPSL/IPO/2526/00258 RJPSL/IPO/2526/00006, RJPSL/IPO/2526/00008, RJPSL/IPO/2526/00020, RJPSL/IPO/2526/00024, RJPSL/IPO/2526/00158, RJPSL/IPO/2526/00159, RJPSL/IPO/2526/00186, RJPSL/IPO/2526/00190 | R35: Estimated
A36: 33 | B36: 196062004 | C36: Electrical | D36: Cables/Fittings/Consumbales | F36: 50000 | H36: =28649+10327+2000+8575+1000+7227+425 -> 58203 | J36: 85350 | K36: 5117.5 | N36: =H36*0.27+I36+J36*0.01149+K36+L36 -> 21812.982 | O36: =F36-N36 -> 28187.018 | P36: RJPSL/BO/2526/00449 RJPSL/BO/2526/00474 RJPDD/BO/2526/00288 RJPSL/BO/2526/00446 RJPSL/BO/2526/00256 RJPSL/BO/2526/00257 RJPSL/BO/2526/00256 RDDPL/BO/2526/00100 RJPSL/BO/2526/00008, RJPSL/BO/2526/00023, RJPSL/BO/2526/00044, RJPSL/BO/2526/00174, RJPSL/BO/2526/00226, RJPSL/BO/2526/00243, RJPSL/BO/2526/00256, RJPSL/BO/2526/00249, RJPSL/BO/2526/00248, RJPSL/BO/2526/00261, RJPSL/BO/2526/00310 | Q36: RJPSL/IPO/2627/00007 RJPSL/IPO/2526/00357 RJPDD/LPO/2526/00059 RJPSL/IPO/2526/00318 RJPSL/IPO/2526/00276 RJPSL/IPO/2526/00261 RJPSL/IPO/2526/00229 RDDPL/IPO/2526/00056 RJPSL/IPO/2526/00009, RJPSL/IPO/2526/00027, RJPSL/IPO/2526/00045, RJPSL/IPO/2526/00099, RJPSL/IPO/2526/00107, RJPSL/IPO/2526/00164, RJPSL/IPO/2526/00168, RJPSL/IPO/2526/00179, RJPSL/IPO/2526/00182, RJPSL/IPO/2526/00185, RJPSL/IPO/2526/00211, RJPSL/IPO/2526/00212 | R36: Estimated
